Workbook
Name Assemblies: Lists!$A$2:$A$9

Sheet Construction and Materials
B2: Construction & Materials Embodied Impacts
B3: Inventory and Impact Assessment
B5: Team: | C5: Island
D7: STV Progress
E9: GWP (kgCO2e) | F9: Energy (MJ) | G9: Water (kg) | H9: ODP (kgCFC11e) | L9: Ozone Depletion Potential
D10: Target | E10: =6.38*10^6*VLOOKUP($C$5,'LCA Data'!B115:K121,10,FALSE) -> 7396873.8 | F10: =1.51*10^8*VLOOKUP(C5,'LCA Data'!B115:M121,12,FALSE) -> 1.5596908e+08 | G10: =VLOOKUP($C$5,'LCA Data'!B115:L121,11,FALSE) -> 2.713874e+08 | H10: (minimize)
D11: Embodied | E11: =SUMIF($J$18:$J$58,">0",E18:E58) -> 4010979.8 | F11: =SUMIF($J$18:$J$58,">0",F18:F58) -> 30756534 | G11: =SUMIF($J$18:$J$58,">0",G18:G58) -> 46676816 | H11: =SUMIF($J$18:$J$58,">0",H18:H58) -> 0.1423865
D12: Used% | E12: =E11/E10 -> 0.54225337 | F12: =F11/F10 -> 0.19719636 | G12: =G11/G10 -> 0.17199331 | H12: -
D13: Use Phase | E13: ='Use Phase'!F13 -> 0 | F13: ='Use Phase'!G13 -> 0 | G13: ='Use Phase'!H13 -> 0 | H13: ='Use Phase'!I13 -> 0
D14: Used% | E14: =E13/E10 -> 0 | F14: =F13/F10 -> 0 | G14: =G13/G10 -> 0 | H14: -
D15: Total% | E15: =E14+E12 -> 0.54225337 | F15: =F14+F12 -> 0.19719636 | G15: =G14+G12 -> 0.17199331 | H15: -
B17: Assembly | C17: Material/Type | D17: Amount | E17: GWP (kgCO2e) | F17: Energy (MJ) | G17: Water (kg) | H17: ODP (kgCFC11e) | I17: Cell Range | J17: Sum? | K17: Num
B18: MEP | C18: Stainless Steel Duct (kg) | D18: =115%*8853 -> 10180.95 | E18: =IF(D18=0,"",D18*VLOOKUP(C18,'LCA Data'!$C$8:$G$107,2,FALSE)*K18) -> 34638.646 | F18: =IF(D18=0,"",D18*VLOOKUP(C18,'LCA Data'!$C$8:$G$107,3,FALSE)*K18) -> 276725.4 | G18: =IF(D18=0,"",D18*VLOOKUP(C18,'LCA Data'!$C$8:$G$107,4,FALSE)*K18) -> 194248.45 | H18: =IF(D18=0,"",D18*VLOOKUP(C18,'LCA Data'!$C$8:$G$107,5,FALSE)*K18) -> 3.6040563e-05 | I18: =IF(B18="Foundation","Lists!B1:B7",IF(B18="Interior Wall","Lists!C1:C6",IF(B18="Exterior Wall","Lists!D1:D11",IF(B18="Floor","Lists!E1:E11",IF(B18="Roof","Lists!F1:F8",IF(B18="Window","Lists!G1:G7",IF(B18="Columns","Lists!H1:H5",IF(B18="Beams","Lists!I1:I5",IF(B18="MEP","Lists!J1:J19",IF(B18="Energy","Lists!K1:K11",IF(B18="Misc","Lists!L1:L9","Lists!M1"))))))))))) -> Lists!J1:J19 | J18: =IF(ISNA(E18),0,1) -> 1 | K18: =IF(D18=0,"",VLOOKUP(C18,'LCA Data'!$C$8:$T$107,18,FALSE)) -> 1
B19: MEP | C19: Air Handling Unit (m^3/s) | D19: =(760+120)*(1/3600)+0.54 -> 0.78444444 | E19: =IF(D19=0,"",D19*VLOOKUP(C19,'LCA Data'!$C$8:$G$107,2,FALSE)*K19) -> 6332.7248 | F19: =IF(D19=0,"",D19*VLOOKUP(C19,'LCA Data'!$C$8:$G$107,3,FALSE)*K19) -> 79255.543 | G19: =IF(D19=0,"",D19*VLOOKUP(C19,'LCA Data'!$C$8:$G$107,4,FALSE)*K19) -> 47833.778 | H19: =IF(D19=0,"",D19*VLOOKUP(C19,'LCA Data'!$C$8:$G$107,5,FALSE)*K19) -> 0.00049738484 | I19: =IF(B19="Foundation","Lists!B1:B7",IF(B19="Interior Wall","Lists!C1:C6",IF(B19="Exterior Wall","Lists!D1:D11",IF(B19="Floor","Lists!E1:E11",IF(B19="Roof","Lists!F1:F8",IF(B19="Window","Lists!G1:G7",IF(B19="Columns","Lists!H1:H5",IF(B19="Beams","Lists!I1:I5",IF(B19="MEP","Lists!J1:J19",IF(B19="Energy","Lists!K1:K11",IF(B19="Misc","Lists!L1:L9","Lists!M1"))))))))))) -> Lists!J1:J19 | J19: =IF(ISNA(E19),0,1) -> 1 | K19: =IF(D19=0,"",VLOOKUP(C19,'LCA Data'!$C$8:$T$107,18,FALSE)) -> 2
B20: Floor | C20: Wood System (sf) | D20: 34275 | E20: =IF(D20=0,"",D20*VLOOKUP(C20,'LCA Data'!$C$8:$G$107,2,FALSE)*K20) -> 272057.33 | F20: =IF(D20=0,"",D20*VLOOKUP(C20,'LCA Data'!$C$8:$G$107,3,FALSE)*K20) -> 3736166.9 | G20: =IF(D20=0,"",D20*VLOOKUP(C20,'LCA Data'!$C$8:$G$107,4,FALSE)*K20) -> 2895143.1 | H20: =IF(D20=0,"",D20*VLOOKUP(C20,'LCA Data'!$C$8:$G$107,5,FALSE)*K20) -> 0.00076997759 | I20: =IF(B20="Foundation","Lists!B1:B7",IF(B20="Interior Wall","Lists!C1:C6",IF(B20="Exterior Wall","Lists!D1:D11",IF(B20="Floor","Lists!E1:E11",IF(B20="Roof","Lists!F1:F8",IF(B20="Window","Lists!G1:G7",IF(B20="Columns","Lists!H1:H5",IF(B20="Beams","Lists!I1:I5",IF(B20="MEP","Lists!J1:J19",IF(B20="Energy","Lists!K1:K11",IF(B20="Misc","Lists!L1:L9","Lists!M1"))))))))))) -> Lists!E1:E11 | J20: =IF(ISNA(E20),0,1) -> 1 | K20: =IF(D20=0,"",VLOOKUP(C20,'LCA Data'!$C$8:$T$107,18,FALSE)) -> 1
B21: Columns | C21: Wood Column (kg) | D21: 2709 | E21: =IF(D21=0,"",D21*VLOOKUP(C21,'LCA Data'!$C$8:$G$107,2,FALSE)*K21) -> 2639.9205 | F21: =IF(D21=0,"",D21*VLOOKUP(C21,'LCA Data'!$C$8:$G$107,3,FALSE)*K21) -> 34690.131 | G21: =IF(D21=0,"",D21*VLOOKUP(C21,'LCA Data'!$C$8:$G$107,4,FALSE)*K21) -> 21494.698 | H21: =IF(D21=0,"",D21*VLOOKUP(C21,'LCA Data'!$C$8:$G$107,5,FALSE)*K21) -> 9.6666331e-06 | I21: =IF(B21="Foundation","Lists!B1:B7",IF(B21="Interior Wall","Lists!C1:C6",IF(B21="Exterior Wall","Lists!D1:D11",IF(B21="Floor","Lists!E1:E11",IF(B21="Roof","Lists!F1:F8",IF(B21="Window","Lists!G1:G7",IF(B21="Columns","Lists!H1:H5",IF(B21="Beams","Lists!I1:I5",IF(B21="MEP","Lists!J1:J19",IF(B21="Energy","Lists!K1:K11",IF(B21="Misc","Lists!L1:L9","Lists!M1"))))))))))) -> Lists!H1:H5 | J21: =IF(ISNA(E21),0,1) -> 1 | K21: =IF(D21=0,"",VLOOKUP(C21,'LCA Data'!$C$8:$T$107,18,FALSE)) -> 1
B22: Foundation | C22: Concrete Slab (cy) | D22: 10337 | E22: =IF(D22=0,"",D22*VLOOKUP(C22,'LCA Data'!$C$8:$G$107,2,FALSE)*K22) -> 3517562.9 | F22: =IF(D22=0,"",D22*VLOOKUP(C22,'LCA Data'!$C$8:$G$107,3,FALSE)*K22) -> 24200140 | G22: =IF(D22=0,"",D22*VLOOKUP(C22,'LCA Data'!$C$8:$G$107,4,FALSE)*K22) -> 41055352 | H22: =IF(D22=0,"",D22*VLOOKUP(C22,'LCA Data'!$C$8:$G$107,5,FALSE)*K22) -> 0.13822776 | I22: =IF(B22="Foundation","Lists!B1:B7",IF(B22="Interior Wall","Lists!C1:C6",IF(B22="Exterior Wall","Lists!D1:D11",IF(B22="Floor","Lists!E1:E11",IF(B22="Roof","Lists!F1:F8",IF(B22="Window","Lists!G1:G7",IF(B22="Columns","Lists!H1:H5",IF(B22="Beams","Lists!I1:I5",IF(B22="MEP","Lists!J1:J19",IF(B22="Energy","Lists!K1:K11",IF(B22="Misc","Lists!L1:L9","Lists!M1"))))))))))) -> Lists!B1:B7 | J22: =IF(ISNA(E22),0,1) -> 1 | K22: =IF(D22=0,"",VLOOKUP(C22,'LCA Data'!$C$8:$T$107,18,FALSE)) -> 1
B23: Interior Wall | C23: Curtain Wall (sf) | D23: 12826 | E23: =IF(D23=0,"",D23*VLOOKUP(C23,'LCA Data'!$C$8:$G$107,2,FALSE)*K23) -> 177748.22 | F23: =IF(D23=0,"",D23*VLOOKUP(C23,'LCA Data'!$C$8:$G$107,3,FALSE)*K23) -> 2429556.2 | G23: =IF(D23=0,"",D23*VLOOKUP(C23,'LCA Data'!$C$8:$G$107,4,FALSE)*K23) -> 2462744 | H23: =IF(D23=0,"",D23*VLOOKUP(C23,'LCA Data'!$C$8:$G$107,5,FALSE)*K23) -> 0.0028456661 | I23: =IF(B23="Foundation","Lists!B1:B7",IF(B23="Interior Wall","Lists!C1:C6",IF(B23="Exterior Wall","Lists!D1:D11",IF(B23="Floor","Lists!E1:E11",IF(B23="Roof","Lists!F1:F8",IF(B23="Window","Lists!G1:G7",IF(B23="Columns","Lists!H1:H5",IF(B23="Beams","Lists!I1:I5",IF(B23="MEP","Lists!J1:J19",IF(B23="Energy","Lists!K1:K11",IF(B23="Misc","Lists!L1:L9","Lists!M1"))))))))))) -> Lists!C1:C6 | J23: =IF(ISNA(E23),0,1) -> 1 | K23: =IF(D23=0,"",VLOOKUP(C23,'LCA Data'!$C$8:$T$107,18,FALSE)) -> 1
B24: Pick Assembly | C24: Pick Type | E24: =IF(D24=0,"",D24*VLOOKUP(C24,'LCA Data'!$C$8:$G$107,2,FALSE)*K24) | F24: =IF(D24=0,"",D24*VLOOKUP(C24,'LCA Data'!$C$8:$G$107,3,FALSE)*K24) | G24: =IF(D24=0,"",D24*VLOOKUP(C24,'LCA Data'!$C$8:$G$107,4,FALSE)*K24) | H24: =IF(D24=0,"",D24*VLOOKUP(C24,'LCA Data'!$C$8:$G$107,5,FALSE)*K24) | I24: =IF(B24="Foundation","Lists!B1:B7",IF(B24="Interior Wall","Lists!C1:C6",IF(B24="Exterior Wall","Lists!D1:D11",IF(B24="Floor","Lists!E1:E11",IF(B24="Roof","Lists!F1:F8",IF(B24="Window","Lists!G1:G7",IF(B24="Columns","Lists!H1:H5",IF(B24="Beams","Lists!I1:I5",IF(B24="MEP","Lists!J1:J19",IF(B24="Energy","Lists!K1:K11",IF(B24="Misc","Lists!L1:L9","Lists!M1"))))))))))) -> Lists!M1 | J24: =IF(ISNA(E24),0,1) -> 1 | K24: =IF(D24=0,"",VLOOKUP(C24,'LCA Data'!$C$8:$T$107,18,FALSE))
B25: Pick Assembly | C25: Pick Type | E25: =IF(D25=0,"",D25*VLOOKUP(C25,'LCA Data'!$C$8:$G$107,2,FALSE)*K25) | F25: =IF(D25=0,"",D25*VLOOKUP(C25,'LCA Data'!$C$8:$G$107,3,FALSE)*K25) | G25: =IF(D25=0,"",D25*VLOOKUP(C25,'LCA Data'!$C$8:$G$107,4,FALSE)*K25) | H25: =IF(D25=0,"",D25*VLOOKUP(C25,'LCA Data'!$C$8:$G$107,5,FALSE)*K25) | I25: =IF(B25="Foundation","Lists!B1:B7",IF(B25="Interior Wall","Lists!C1:C6",IF(B25="Exterior Wall","Lists!D1:D11",IF(B25="Floor","Lists!E1:E11",IF(B25="Roof","Lists!F1:F8",IF(B25="Window","Lists!G1:G7",IF(B25="Columns","Lists!H1:H5",IF(B25="Beams","Lists!I1:I5",IF(B25="MEP","Lists!J1:J19",IF(B25="Energy","Lists!K1:K11",IF(B25="Misc","Lists!L1:L9","Lists!M1"))))))))))) -> Lists!M1 | J25: =IF(ISNA(E25),0,1) -> 1 | K25: =IF(D25=0,"",VLOOKUP(C25,'LCA Data'!$C$8:$T$107,18,FALSE))
B26: Pick Assembly | C26: Pick Type | E26: =IF(D26=0,"",D26*VLOOKUP(C26,'LCA Data'!$C$8:$G$107,2,FALSE)*K26) | F26: =IF(D26=0,"",D26*VLOOKUP(C26,'LCA Data'!$C$8:$G$107,3,FALSE)*K26) | G26: =IF(D26=0,"",D26*VLOOKUP(C26,'LCA Data'!$C$8:$G$107,4,FALSE)*K26) | H26: =IF(D26=0,"",D26*VLOOKUP(C26,'LCA Data'!$C$8:$G$107,5,FALSE)*K26) | I26: =IF(B26="Foundation","Lists!B1:B7",IF(B26="Interior Wall","Lists!C1:C6",IF(B26="Exterior Wall","Lists!D1:D11",IF(B26="Floor","Lists!E1:E11",IF(B26="Roof","Lists!F1:F8",IF(B26="Window","Lists!G1:G7",IF(B26="Columns","Lists!H1:H5",IF(B26="Beams","Lists!I1:I5",IF(B26="MEP","Lists!J1:J19",IF(B26="Energy","Lists!K1:K11",IF(B26="Misc","Lists!L1:L9","Lists!M1"))))))))))) -> Lists!M1 | J26: =IF(ISNA(E26),0,1) -> 1 | K26: =IF(D26=0,"",VLOOKUP(C26,'LCA Data'!$C$8:$T$107,18,FALSE))
B27: Pick Assembly | C27: Pick Type | E27: =IF(D27=0,"",D27*VLOOKUP(C27,'LCA Data'!$C$8:$G$107,2,FALSE)*K27) | F27: =IF(D27=0,"",D27*VLOOKUP(C27,'LCA Data'!$C$8:$G$107,3,FALSE)*K27) | G27: =IF(D27=0,"",D27*VLOOKUP(C27,'LCA Data'!$C$8:$G$107,4,FALSE)*K27) | H27: =IF(D27=0,"",D27*VLOOKUP(C27,'LCA Data'!$C$8:$G$107,5,FALSE)*K27) | I27: =IF(B27="Foundation","Lists!B1:B7",IF(B27="Interior Wall","Lists!C1:C6",IF(B27="Exterior Wall","Lists!D1:D11",IF(B27="Floor","Lists!E1:E11",IF(B27="Roof","Lists!F1:F8",IF(B27="Window","Lists!G1:G7",IF(B27="Columns","Lists!H1:H5",IF(B27="Beams","Lists!I1:I5",IF(B27="MEP","Lists!J1:J19",IF(B27="Energy","Lists!K1:K11",IF(B27="Misc","Lists!L1:L9","Lists!M1"))))))))))) -> Lists!M1 | J27: =IF(ISNA(E27),0,1) -> 1 | K27: =IF(D27=0,"",VLOOKUP(C27,'LCA Data'!$C$8:$T$107,18,FALSE))
B28: Pick Assembly | C28: Pick Type | E28: =IF(D28=0,"",D28*VLOOKUP(C28,'LCA Data'!$C$8:$G$107,2,FALSE)*K28) | F28: =IF(D28=0,"",D28*VLOOKUP(C28,'LCA Data'!$C$8:$G$107,3,FALSE)*K28) | G28: =IF(D28=0,"",D28*VLOOKUP(C28,'LCA Data'!$C$8:$G$107,4,FALSE)*K28) | H28: =IF(D28=0,"",D28*VLOOKUP(C28,'LCA Data'!$C$8:$G$107,5,FALSE)*K28) | I28: =IF(B28="Foundation","Lists!B1:B7",IF(B28="Interior Wall","Lists!C1:C6",IF(B28="Exterior Wall","Lists!D1:D11",IF(B28="Floor","Lists!E1:E11",IF(B28="Roof","Lists!F1:F8",IF(B28="Window","Lists!G1:G7",IF(B28="Columns","Lists!H1:H5",IF(B28="Beams","Lists!I1:I5",IF(B28="MEP","Lists!J1:J19",IF(B28="Energy","Lists!K1:K11",IF(B28="Misc","Lists!L1:L9","Lists!M1"))))))))))) -> Lists!M1 | J28: =IF(ISNA(E28),0,1) -> 1 | K28: =IF(D28=0,"",VLOOKUP(C28,'LCA Data'!$C$8:$T$107,18,FALSE))
B29: Pick Assembly | C29: Pick Type | E29: =IF(D29=0,"",D29*VLOOKUP(C29,'LCA Data'!$C$8:$G$107,2,FALSE)*K29) | F29: =IF(D29=0,"",D29*VLOOKUP(C29,'LCA Data'!$C$8:$G$107,3,FALSE)*K29) | G29: =IF(D29=0,"",D29*VLOOKUP(C29,'LCA Data'!$C$8:$G$107,4,FALSE)*K29) | H29: =IF(D29=0,"",D29*VLOOKUP(C29,'LCA Data'!$C$8:$G$107,5,FALSE)*K29) | I29: =IF(B29="Foundation","Lists!B1:B7",IF(B29="Interior Wall","Lists!C1:C6",IF(B29="Exterior Wall","Lists!D1:D11",IF(B29="Floor","Lists!E1:E11",IF(B29="Roof","Lists!F1:F8",IF(B29="Window","Lists!G1:G7",IF(B29="Columns","Lists!H1:H5",IF(B29="Beams","Lists!I1:I5",IF(B29="MEP","Lists!J1:J19",IF(B29="Energy","Lists!K1:K11",IF(B29="Misc","Lists!L1:L9","Lists!M1"))))))))))) -> Lists!M1 | J29: =IF(ISNA(E29),0,1) -> 1 | K29: =IF(D29=0,"",VLOOKUP(C29,'LCA Data'!$C$8:$T$107,18,FALSE))
B30: Pick Assembly | C30: Pick Type | E30: =IF(D30=0,"",D30*VLOOKUP(C30,'LCA Data'!$C$8:$G$107,2,FALSE)*K30) | F30: =IF(D30=0,"",D30*VLOOKUP(C30,'LCA Data'!$C$8:$G$107,3,FALSE)*K30) | G30: =IF(D30=0,"",D30*VLOOKUP(C30,'LCA Data'!$C$8:$G$107,4,FALSE)*K30) | H30: =IF(D30=0,"",D30*VLOOKUP(C30,'LCA Data'!$C$8:$G$107,5,FALSE)*K30) | I30: =IF(B30="Foundation","Lists!B1:B7",IF(B30="Interior Wall","Lists!C1:C6",IF(B30="Exterior Wall","Lists!D1:D11",IF(B30="Floor","Lists!E1:E11",IF(B30="Roof","Lists!F1:F8",IF(B30="Window","Lists!G1:G7",IF(B30="Columns","Lists!H1:H5",IF(B30="Beams","Lists!I1:I5",IF(B30="MEP","Lists!J1:J19",IF(B30="Energy","Lists!K1:K11",IF(B30="Misc","Lists!L1:L9","Lists!M1"))))))))))) -> Lists!M1 | J30: =IF(ISNA(E30),0,1) -> 1 | K30: =IF(D30=0,"",VLOOKUP(C30,'LCA Data'!$C$8:$T$107,18,FALSE))
B31: Pick Assembly | C31: Pick Type | E31: =IF(D31=0,"",D31*VLOOKUP(C31,'LCA Data'!$C$8:$G$107,2,FALSE)*K31) | F31: =IF(D31=0,"",D31*VLOOKUP(C31,'LCA Data'!$C$8:$G$107,3,FALSE)*K31) | G31: =IF(D31=0,"",D31*VLOOKUP(C31,'LCA Data'!$C$8:$G$107,4,FALSE)*K31) | H31: =IF(D31=0,"",D31*VLOOKUP(C31,'LCA Data'!$C$8:$G$107,5,FALSE)*K31) | I31: =IF(B31="Foundation","Lists!B1:B7",IF(B31="Interior Wall","Lists!C1:C6",IF(B31="Exterior Wall","Lists!D1:D11",IF(B31="Floor","Lists!E1:E11",IF(B31="Roof","Lists!F1:F8",IF(B31="Window","Lists!G1:G7",IF(B31="Columns","Lists!H1:H5",IF(B31="Beams","Lists!I1:I5",IF(B31="MEP","Lists!J1:J19",IF(B31="Energy","Lists!K1:K11",IF(B31="Misc","Lists!L1:L9","Lists!M1"))))))))))) -> Lists!M1 | J31: =IF(ISNA(E31),0,1) -> 1 | K31: =IF(D31=0,"",VLOOKUP(C31,'LCA Data'!$C$8:$T$107,18,FALSE))
B32: Pick Assembly | C32: Pick Type | E32: =IF(D32=0,"",D32*VLOOKUP(C32,'LCA Data'!$C$8:$G$107,2,FALSE)*K32) | F32: =IF(D32=0,"",D32*VLOOKUP(C32,'LCA Data'!$C$8:$G$107,3,FALSE)*K32) | G32: =IF(D32=0,"",D32*VLOOKUP(C32,'LCA Data'!$C$8:$G$107,4,FALSE)*K32) | H32: =IF(D32=0,"",D32*VLOOKUP(C32,'LCA Data'!$C$8:$G$107,5,FALSE)*K32) | I32: =IF(B32="Foundation","Lists!B1:B7",IF(B32="Interior Wall","Lists!C1:C6",IF(B32="Exterior Wall","Lists!D1:D11",IF(B32="Floor","Lists!E1:E11",IF(B32="Roof","Lists!F1:F8",IF(B32="Window","Lists!G1:G7",IF(B32="Columns","Lists!H1:H5",IF(B32="Beams","Lists!I1:I5",IF(B32="MEP","Lists!J1:J19",IF(B32="Energy","Lists!K1:K11",IF(B32="Misc","Lists!L1:L9","Lists!M1"))))))))))) -> Lists!M1 | J32: =IF(ISNA(E32),0,1) -> 1 | K32: =IF(D32=0,"",VLOOKUP(C32,'LCA Data'!$C$8:$T$107,18,FALSE))
B33: Pick Assembly | C33: Pick Type | E33: =IF(D33=0,"",D33*VLOOKUP(C33,'LCA Data'!$C$8:$G$107,2,FALSE)*K33) | F33: =IF(D33=0,"",D33*VLOOKUP(C33,'LCA Data'!$C$8:$G$107,3,FALSE)*K33) | G33: =IF(D33=0,"",D33*VLOOKUP(C33,'LCA Data'!$C$8:$G$107,4,FALSE)*K33) | H33: =IF(D33=0,"",D33*VLOOKUP(C33,'LCA Data'!$C$8:$G$107,5,FALSE)*K33) | I33: =IF(B33="Foundation","Lists!B1:B7",IF(B33="Interior Wall","Lists!C1:C6",IF(B33="Exterior Wall","Lists!D1:D11",IF(B33="Floor","Lists!E1:E11",IF(B33="Roof","Lists!F1:F8",IF(B33="Window","Lists!G1:G7",IF(B33="Columns","Lists!H1:H5",IF(B33="Beams","Lists!I1:I5",IF(B33="MEP","Lists!J1:J19",IF(B33="Energy","Lists!K1:K11",IF(B33="Misc","Lists!L1:L9","Lists!M1"))))))))))) -> Lists!M1 | J33: =IF(ISNA(E33),0,1) -> 1 | K33: =IF(D33=0,"",VLOOKUP(C33,'LCA Data'!$C$8:$T$107,18,FALSE))
B34: Pick Assembly | C34: Pick Type | E34: =IF(D34=0,"",D34*VLOOKUP(C34,'LCA Data'!$C$8:$G$107,2,FALSE)*K34) | F34: =IF(D34=0,"",D34*VLOOKUP(C34,'LCA Data'!$C$8:$G$107,3,FALSE)*K34) | G34: =IF(D34=0,"",D34*VLOOKUP(C34,'LCA Data'!$C$8:$G$107,4,FALSE)*K34) | H34: =IF(D34=0,"",D34*VLOOKUP(C34,'LCA Data'!$C$8:$G$107,5,FALSE)*K34) | I34: =IF(B34="Foundation","Lists!B1:B7",IF(B34="Interior Wall","Lists!C1:C6",IF(B34="Exterior Wall","Lists!D1:D11",IF(B34="Floor","Lists!E1:E11",IF(B34="Roof","Lists!F1:F8",IF(B34="Window","Lists!G1:G7",IF(B34="Columns","Lists!H1:H5",IF(B34="Beams","Lists!I1:I5",IF(B34="MEP","Lists!J1:J19",IF(B34="Energy","Lists!K1:K11",IF(B34="Misc","Lists!L1:L9","Lists!M1"))))))))))) -> Lists!M1 | J34: =IF(ISNA(E34),0,1) -> 1 | K34: =IF(D34=0,"",VLOOKUP(C34,'LCA Data'!$C$8:$T$107,18,FALSE))
B35: Pick Assembly | C35: Pick Type | E35: =IF(D35=0,"",D35*VLOOKUP(C35,'LCA Data'!$C$8:$G$107,2,FALSE)*K35) | F35: =IF(D35=0,"",D35*VLOOKUP(C35,'LCA Data'!$C$8:$G$107,3,FALSE)*K35) | G35: =IF(D35=0,"",D35*VLOOKUP(C35,'LCA Data'!$C$8:$G$107,4,FALSE)*K35) | H35: =IF(D35=0,"",D35*VLOOKUP(C35,'LCA Data'!$C$8:$G$107,5,FALSE)*K35) | I35: =IF(B35="Foundation","Lists!B1:B7",IF(B35="Interior Wall","Lists!C1:C6",IF(B35="Exterior Wall","Lists!D1:D11",IF(B35="Floor","Lists!E1:E11",IF(B35="Roof","Lists!F1:F8",IF(B35="Window","Lists!G1:G7",IF(B35="Columns","Lists!H1:H5",IF(B35="Beams","Lists!I1:I5",IF(B35="MEP","Lists!J1:J19",IF(B35="Energy","Lists!K1:K11",IF(B35="Misc","Lists!L1:L9","Lists!M1"))))))))))) -> Lists!M1 | J35: =IF(ISNA(E35),0,1) -> 1 | K35: =IF(D35=0,"",VLOOKUP(C35,'LCA Data'!$C$8:$T$107,18,FALSE))
... B58: Pick Assembly | C58: Pick Type | E58: =IF(D58=0,"",D58*VLOOKUP(C58,'LCA Data'!$C$8:$G$107,2,FALSE)*K58) | F58: =IF(D58=0,"",D58*VLOOKUP(C58,'LCA Data'!$C$8:$G$107,3,FALSE)*K58) | G58: =IF(D58=0,"",D58*VLOOKUP(C58,'LCA Data'!$C$8:$G$107,4,FALSE)*K58) | H58: =IF(D58=0,"",D58*VLOOKUP(C58,'LCA Data'!$C$8:$G$107,5,FALSE)*K58) | I58: =IF(B58="Foundation","Lists!B1:B7",IF(B58="Interior Wall","Lists!C1:C6",IF(B58="Exterior Wall","Lists!D1:D11",IF(B58="Floor","Lists!E1:E11",IF(B58="Roof","Lists!F1:F8",IF(B58="Window","Lists!G1:G7",IF(B58="Columns","Lists!H1:H5",IF(B58="Beams","Lists!I1:I5",IF(B58="MEP","Lists!J1:J19",IF(B58="Energy","Lists!K1:K11",IF(B58="Misc","Lists!L1:L9","Lists!M1"))))))))))) -> Lists!M1 | J58: =IF(ISNA(E58),0,1) -> 1 | K58: =IF(D58=0,"",VLOOKUP(C58,'LCA Data'!$C$8:$T$107,18,FALSE))

Sheet Use Phase
B2: Use Phase Impacts
B3: Inventory and Impact Assessment
B5: Team: | C5: Island
E7: STV Progress
F9: GWP (kgCO2e) | G9: Energy (MJ) | H9: Water (kg) | I9: ODP (kgCFC11e)
E10: Target | F10: =6.38*10^6*VLOOKUP($C$5,'LCA Data'!B115:L121,10,FALSE) -> 7396873.8 | G10: =1.51*10^8*VLOOKUP(C5,'LCA Data'!B115:M121,12,FALSE) -> 1.5596908e+08 | H10: =VLOOKUP($C$5,'LCA Data'!B115:M121,11,FALSE) -> 2.713874e+08 | I10: (minimize)
E11: Embodied | F11: ='Construction and Materials'!E11 -> 4010979.8 | G11: ='Construction and Materials'!F11 -> 30756534 | H11: ='Construction and Materials'!G11 -> 46676816 | I11: ='Construction and Materials'!H11 -> 0.1423865
E12: Used% | F12: =F11/F10 -> 0.54225337 | G12: =G11/G10 -> 0.19719636 | H12: =H11/H10 -> 0.17199331 | I12: -
E13: Use Phase | F13: =(F19+F23+F25+F27+F29+F39+F40)*50 -> 0 | G13: =(G19+G23+G25+G27+G29+G39+G40)*50 -> 0 | H13: =(H19+H23+H25+H27+H29+H39+H40)*50 -> 0 | I13: =(I19+I23+I25+I27+I29+I39+I40)*50 -> 0
E14: Used% | F14: =F13/F10 -> 0 | G14: =G13/G10 -> 0 | H14: =H13/H10 -> 0 | I14: -
E15: Total% | F15: =F14+F12 -> 0.54225337 | G15: =G14+G12 -> 0.19719636 | H15: =H14+H12 -> 0.17199331 | I15: -
F17: Annual Impacts
B18: Energy Use | F18: GWP (kgCO2e) | G18: Energy (MJ) | H18: Water (kg) | I18: ODP (kgCFC11e)
B19: Electricity Drawn from Grid: | E19: kWh | F19: =VLOOKUP($C$5,'LCA Data'!B115:J121,2,FALSE)*$D$19 -> 0 | G19: =VLOOKUP($C$5,'LCA Data'!B115:J121,7,FALSE)*$D$19 -> 0 | H19: =VLOOKUP($C$5,'LCA Data'!B115:J121,8,FALSE)*$D$19 -> 0 | I19: =VLOOKUP($C$5,'LCA Data'!B115:J121,9,FALSE)*$D$19 -> 0
B20: On-site Renewable Electricity: | E20: kWh | F20: =0*$D$20 -> 0 | G20: =0*$D$20 -> 0 | H20: =0*$D$20 -> 0 | I20: =0*$D$20 -> 0
B21: =IF(C5="Ridge","District Heating:","Cogeneration:") -> Cogeneration:
C22: Fuel Type | D22: Select Fuel
C23: =IF($C$5="Atlantic","Thermal Energy","Electricity") -> Electricity | E23: kWh | F23: =IF($D$22="Select Fuel",0,$D23*(1/($D$24+$D$26+$D$28))*VLOOKUP($D$22,'Cogen Data'!$B$5:$J$14,9,FALSE)*($D$24/($D$24+$D$26+$D$28))*3.6) -> 0 | G23: =IF($D$22="Select Fuel",0,$D23*(1/($D$24+$D$26+$D$28))*($D$24/($D$24+$D$26+$D$28))*3.6) -> 0 | H23: =IF($D$22="Select Fuel",0,$D23*(1/($D$24+$D$26+$D$28))*VLOOKUP($D$22,'Cogen Data'!$B$5:$J$14,6,FALSE)/VLOOKUP($D$22,'Cogen Data'!$B$5:$J$14,8,FALSE)*($D$24/($D$24+$D$26+$D$28))*3.6) -> 0 | I23: =IF($D$22="Select Fuel",0,$D23*(1/($D$24+$D$26+$D$28))*VLOOKUP($D$22,'Cogen Data'!$B$5:$J$14,7,FALSE)/VLOOKUP($D$22,'Cogen Data'!$B$5:$J$14,8,FALSE)*($D$24/($D$24+$D$26+$D$28))*3.6) -> 0
C24: Electricity Split | D24: 0
C25: Heating | E25: MJ | F25: =IF($D$22="Select Fuel",0,$D25*(1/($D$24+$D$26+$D$28))*VLOOKUP($D$22,'Cogen Data'!$B$5:$J$14,9,FALSE)*($D$26/($D$24+$D$26+$D$28))) -> 0 | G25: =IF($D$22="Select Fuel",0,$D25*(1/($D$24+$D$26+$D$28))*($D$26/($D$24+$D$26+$D$28))) -> 0 | H25: =IF($D$22="Select Fuel",0,$D25*(1/($D$24+$D$26+$D$28))*VLOOKUP($D$22,'Cogen Data'!$B$5:$J$14,6,FALSE)/VLOOKUP($D$22,'Cogen Data'!$B$5:$J$14,8,FALSE)*($D$26/($D$24+$D$26+$D$28))) -> 0 | I25: =IF($D$22="Select Fuel",0,$D25*(1/($D$24+$D$26+$D$28))*VLOOKUP($D$22,'Cogen Data'!$B$5:$J$14,7,FALSE)/VLOOKUP($D$22,'Cogen Data'!$B$5:$J$14,8,FALSE)*($D$26/($D$24+$D$26+$D$28))) -> 0
C26: Heating Split | D26: 0
C27: Cooling | E27: kWh | F27: =IF($D$22="Select Fuel",0,$D27*(1/($D$24+$D$26+$D$28))*VLOOKUP($D$22,'Cogen Data'!$B$5:$J$14,9,FALSE)*($D$28/($D$24+$D$26+$D$28))*3.6) -> 0 | G27: =IF($D$22="Select Fuel",0,$D27*(1/($D$24+$D$26+$D$28))*($D$28/($D$24+$D$26+$D$28))*3.6) -> 0 | H27: =IF($D$22="Select Fuel",0,$D27*(1/($D$24+$D$26+$D$28))*VLOOKUP($D$22,'Cogen Data'!$B$5:$J$14,6,FALSE)/VLOOKUP($D$22,'Cogen Data'!$B$5:$J$14,8,FALSE)*($D$28/($D$24+$D$26+$D$28))*3.6) -> 0 | I27: =IF($D$22="Select Fuel",0,$D27*(1/($D$24+$D$26+$D$28))*VLOOKUP($D$22,'Cogen Data'!$B$5:$J$14,7,FALSE)/VLOOKUP($D$22,'Cogen Data'!$B$5:$J$14,8,FALSE)*($D$28/($D$24+$D$26+$D$28))*3.6) -> 0
C28: Cooling Split | D28: 0
B29: Natural Gas Use: | E29: m^3 | F29: =$D$29*37*10^6/(1.055*10^9)*(117/2.2) + $D$29*0.38 -> 0 | G29: =37*D29 -> 0 | H29: =0.00618*1000*$D$29 -> 0 | I29: =$D$29*3.07*10^-7 -> 0
B31: Water Use | F31: GWP (kgCO2e) | G31: Energy (MJ) | H31: Water (kg) | I31: ODP (kgCFC11e)
B32: Toilet Flow Rate: | D32: 0 | E32: gal/flush | F32: =900*3*250*IF(NOT(ISBLANK($D$33)),0.75,1)*$D32*0.000317*3.79 -> 0 | G32: =900*3*250*IF(NOT(ISBLANK($D$33)),0.75,1)*$D32*8.44*10^-5*41.868*3.79 -> 0 | H32: =900*3*250*IF(NOT(ISBLANK($D$33)),0.75,1)*$D32*(1+0.00113*1000)*3.79 -> 0 | I32: =900*3*250*IF(NOT(ISBLANK($D$33)),0.75,1)*$D32*1.62*10^-11*3.79 -> 0
B33: Urinal Flow Rate: | D33: 0 | E33: gal/flush | F33: =900*3*250*0.25*$D33*0.000317*3.79 -> 0 | G33: =900*3*250*0.25*$D33*8.44*10^-5*41.868*3.79 -> 0 | H33: =900*3*250*0.25*$D33*(1+0.00113*1000)*3.79 -> 0 | I33: =900*3*250*0.25*$D33*1.62*10^-11*3.79 -> 0
B34: WC Sink Flow Rate: | D34: 0 | E34: gal/min | F34: =900*0.5*3*250*$D34*0.000317*3.79 -> 0 | G34: =900*0.5*3*250*$D34*8.44*10^-5*41.868*3.79 -> 0 | H34: =900*0.5*3*250*$D34*(1+0.00113*1000)*3.79 -> 0 | I34: =900*0.5*3*250*$D34*1.62*10^-11*3.79 -> 0
B35: Lab Sink Flow Rate: | D35: 0 | E35: gal/min | F35: =900*0.2*1*250*$D35*0.000317*3.79 -> 0 | G35: =900*0.2*1*250*$D35*8.44*10^-5*41.868*3.79 -> 0 | H35: =900*0.2*1*250*$D35*(1+0.00113*1000)*3.79 -> 0 | I35: =900*0.2*1*250*$D35*1.62*10^-11*3.79 -> 0
B36: Kitchen Sink Flow Rate: | D36: 0 | E36: gal/min | F36: =900*0.25*1*250*$D36*0.000317*3.79 -> 0 | G36: =900*0.25*1*250*$D36*8.44*10^-5*41.868*3.79 -> 0 | H36: =900*0.25*1*250*$D36*(1+0.00113*1000)*3.79 -> 0 | I36: =900*0.25*1*250*$D36*1.62*10^-11*3.79 -> 0
B37: Shower Flow Rate: | D37: 0 | E37: gal/min | F37: =900*0.01*10*250*$D37*0.000317*3.79 -> 0 | G37: =900*0.01*10*250*$D37*8.44*10^-5*41.868*3.79 -> 0 | H37: =900*0.01*10*250*$D37*(1+0.00113*1000)*3.79 -> 0 | I37: =900*0.01*10*250*$D37*1.62*10^-11*3.79 -> 0
B38: Landscaping Water Use: | E38: gal | F38: =$D38*0.000317*3.79 -> 0 | G38: =$D38*8.44*10^-5*41.868*3.79 -> 0 | H38: =$D38*(1+0.00113*1000)*3.79 -> 0 | I38: =$D38*1.62*10^-11*3.79 -> 0
B39: Total | D39: 3 | F39: =SUM(F32:F38) -> 0 | G39: =SUM(G32:G38) -> 0 | H39: =SUM(H32:H38) -> 0 | I39: =SUM(I32:I38) -> 0
B40: Rainwater Collection: | E40: gal | F40: 0 | G40: 0 | H40: =-MIN(D40*(1+0.00113*1000)*3.79,H32+H33+H38) -> 0 | I40: 0

Sheet Results
B2: Life Cycle Assessment Results Overview
B3: Total Life Cycle Impacts
B6: Performance Relative to Life Cycle Impact Targets
B8: Impact | C8: Target | D8: Project | E8: %
B9: Carbon (kgCO2e) | C9: ='Construction and Materials'!E10 -> 7396873.8 | D9: ='Construction and Materials'!E11+'Construction and Materials'!E13 -> 4010979.8 | E9: =D9/C9 -> 0.54225337 | F9: 1
B10: Energy (MJ) | C10: ='Construction and Materials'!F10 -> 1.5596908e+08 | D10: ='Construction and Materials'!F11+'Construction and Materials'!F13 -> 30756534 | E10: =D10/C10 -> 0.19719636 | F10: 1
B11: Water (kgH2O) | C11: ='Construction and Materials'!G10 -> 2.713874e+08 | D11: ='Construction and Materials'!G11+'Construction and Materials'!G13 -> 46676816 | E11: =D11/C11 -> 0.17199331 | F11: 1
B12: Ozone (kgCFC11e) | C12: - | D12: ='Construction and Materials'!H11+'Construction and Materials'!H13 -> 0.1423865 | E12: -
B27: Breakdown of Embodied vs. Use Phase Impacts
C29: Embodied | F29: Use-Phase | I29: Total
B30: Impact | C30: Materials | D30: Transport | E30: Construction | F30: Electricity | G30: Heating | H30: Water Use | I30: Life Cycle
B31: Carbon (kgCO2e) | C31: =Lists!S47 -> 3514655.9 | D31: =Lists!T47 -> 144763.81 | E31: =Lists!U47 -> 348393.77 | F31: =('Use Phase'!F19+'Use Phase'!F20+'Use Phase'!F23+'Use Phase'!F27)*50 -> 0 | G31: =('Use Phase'!F25+'Use Phase'!F29)*50 -> 0 | H31: =('Use Phase'!F39+'Use Phase'!F40)*50 -> 0 | I31: =SUM(C31:H31) -> 4007813.4 | J31: =I31-D9 -> -3166.3624
B32: %Total | C32: =C31/$I$31 -> 0.87695096 | D32: =D31/$I$31 -> 0.036120396 | E32: =E31/$I$31 -> 0.086928639 | F32: =F31/$I$31 -> 0 | G32: =G31/$I$31 -> 0 | H32: =H31/$I$31 -> 0 | I32: =I31/$I$31 -> 1
B33: Energy (MJ) | C33: =Lists!W47 -> 23508158 | D33: =Lists!X47 -> 2223532.3 | E33: =Lists!Y47 -> 4985215.8 | F33: =('Use Phase'!G19+'Use Phase'!G20+'Use Phase'!G23+'Use Phase'!G27)*50 -> 0 | G33: =('Use Phase'!G25+'Use Phase'!G29)*50 -> 0 | H33: =('Use Phase'!G39+'Use Phase'!G40)*50 -> 0 | I33: =SUM(C33:H33) -> 30716906 | J33: =I33-D10 -> -39627.771
B34: %Total | C34: =C33/$I$33 -> 0.7653166 | D34: =D33/$I$33 -> 0.072387899 | E34: =E33/$I$33 -> 0.1622955 | F34: =F33/$I$33 -> 0 | G34: =G33/$I$33 -> 0 | H34: =H33/$I$33 -> 0 | I34: =I33/$I$33 -> 1
B35: Water (kgH2O) | C35: =Lists!AA47 -> 40852762 | D35: =Lists!AB47 -> 515807.91 | E35: =Lists!AC47 -> 5284328.7 | F35: =('Use Phase'!H19+'Use Phase'!H20+'Use Phase'!H23+'Use Phase'!H27)*50 -> 0 | G35: =('Use Phase'!H25+'Use Phase'!H29)*50 -> 0 | H35: =('Use Phase'!H39+'Use Phase'!H40)*50 -> 0 | I35: =SUM(C35:H35) -> 46652899 | J35: =I35-D11 -> -23916.889
B36: %Total | C36: =C35/$I$35 -> 0.87567468 | D36: =D35/$I$35 -> 0.011056288 | E36: =E35/$I$35 -> 0.11326903 | F36: =F35/$I$35 -> 0 | G36: =G35/$I$35 -> 0 | H36: =H35/$I$35 -> 0 | I36: =I35/$I$35 -> 1
B37: Ozone (kgCFC11e) | C37: =Lists!AE47 -> 0.11916976 | D37: =Lists!AF47 -> 0.022953554 | E37: =Lists!AG47 -> 1.4492233e-05 | F37: =('Use Phase'!I19+'Use Phase'!I20+'Use Phase'!I23+'Use Phase'!I27)*50 -> 0 | G37: =('Use Phase'!I25+'Use Phase'!I29)*50 -> 0 | H37: =('Use Phase'!I39+'Use Phase'!I40)*50 -> 0 | I37: =SUM(C37:H37) -> 0.14213781 | J37: =I37-D12 -> -0.00024869242
B38: %Total | C38: =C37/$I$37 -> 0.83841002 | D38: =D37/$I$37 -> 0.16148803 | E38: =E37/$I$37 -> 0.00010195903 | F38: =F37/$I$37 -> 0 | G38: =G37/$I$37 -> 0 | H38: =H37/$I$37 -> 0 | I38: =I37/$I$37 -> 1
B41: Embodied Carbon (kgCO2e) | D41: =SUM(C31:E31) -> 4007813.4 | E41: =SUM(C32:E32) -> 1 | H41: Total Life Cycle Carbon (kgCO2e)
B61: Embodied Energy (MJ) | D61: =SUM(C33:E33) -> 30716906 | E61: =SUM(C34:E34) -> 1 | H61: Total Life Cycle Energy (MJ)
B81: Embodied Water (kgH2O) | D81: =SUM(C35:E35) -> 46652899 | E81: =SUM(C36:E36) -> 1 | H81: Total Life Cycle Water (kgH2O)
B101: Embodied ODP (kgCFC11e) | D101: =SUM(C37:E37) -> 0.14213781 | E101: =SUM(C38:E38) -> 1 | H101: Total Life Cycle ODP (kgCFC11e)
B122: Carbon (kgCO2e) Accrual Over Project Life
B154: Excess Carbon | C154: =Lists!CJ49/1000 -> 0 | D154: mtCO2e | F154: Total Cost | G154: =Lists!CK51 -> 0

Sheet Cogen Data
B2: 1 | C2: 2 | D2: 3 | E2: 4 | F2: 5 | G2: 6 | H2: 7 | I2: 8 | J2: 9
B4: Select Fuel | C4: FU unit | D4: kg/m^3 | E4: CO2 | F4: MJ | G4: H2O | H4: ODP | I4: MJ/kg | J4: kgCO2/MJ | L4: http://www.ocean.washington.edu/courses/envir215/energynumbers.pdf
B5: Lignite | C5: kg | D5: - | E5: 0.1277 | F5: 26.000028 | G5: 0.0346 | H5: 1.6e-11 | I5: 15 | J5: 0.092799548 | L5: https://www.princeton.edu/~achaney/tmve/wiki100k/docs/Lignite.html
B6: Anthracite | C6: kg | D6: - | E6: 0.301 | F6: 28.135296 | G6: 2.4 | H6: 9.02e-09 | I6: 30 | J6: 0.098486428 | L6: http://en.wikipedia.org/wiki/Anthracite
B7: Gasoline | C7: kg | D7: - | E7: 0.6876 | F7: 51.49764 | G7: 0.0451 | H7: 9.96e-09 | I7: 43.835616 | J7: 0.067725575 | L7: http://cta.ornl.gov/bedb/appendix_a/Lower_and_Higher_Heating_Values_of_Gas_Liquid_and_Solid_Fuels.pdf
B8: Diesel | C8: m^3-->kg | D8: 832 | E8: 0.53941106 | F8: 53.253228 | G8: 0.06784666 | H8: 1.5504808e-10 | I8: 43 | J8: 0.069491955 | L8: http://www.biogas-renewable-energy.info/biogas_composition.html
B9: Heavy Fuel Oil | C9: kg | D9: - | E9: 0.4267 | F9: 52.075418 | G9: 4.2 | H9: 4.5e-07 | I9: 39.466 | J9: 0.078 | L9: http://www.biomassenergycentre.org.uk/portal/page?_pageid=75,163182&_dad=portal&_schema=PORTAL
B10: Corn Ethanol | C10: kg | D10: - | E10: 1.897 | F10: 18.924336 | G10: 26.9 | H10: 1.71e-07 | I10: 29.620253 | J10: 0.072 | L10: http://wogone.com/science/the_energy_and_fuel_data_sheet.pdf
B11: Natural Gas | C11: m^3-->kg | D11: 0.668 | E11: 0.56916168 | F11: 63.917644 | G11: 0.47305389 | H11: 3.07e-07 | I11: 47.141 | J11: 0.05040644 | L11: http://cdm.unfccc.int/Panels/ssc_wg/SSCWG05_repan_07_Scenario_NRB2RB.pdf
B12: Propane | C12: kg | D12: - | E12: 0.696 | F12: 54.00972 | G12: 4 | H12: 7.46e-07 | I12: 46.3 | J12: 0.059884574 | L12: http://www.biogas.org.nz/background.asp
B13: Sewage Biogas | C13: m^3-->kg | D13: 0.93 | E13: 0.41634409 | F13: 5.5869019 | G13: 1.588172 | H13: 4.7419355e-08 | I13: 21.6 | J13: 0.018518519
B14: Wood Pellet | C14: kg | D14: - | E14: 0.159 | F14: 1.967796 | G14: 1 | H14: 9.26e-09 | I14: 16 | J14: 0.10275
B16: 1 | C16: 2 | D16: 3 | E16: 4 | F16: 5 | G16: 6 | H16: 7 | I16: 8
B18: Team | C18: Elec. Nu | D18: Therm. Nu | E18: Cool. Nu | F18: Tot. Nu | G18: Elec. Frac. | H18: Therm. Frac | I18: Cool. Frac
B19: Express | C19: 0.25 | D19: 0.5 | E19: 0 | F19: 0.75 | G19: 0.33333333 | H19: 0.66666667 | I19: 0
B20: Central | C20: 0.3 | D20: 0.3 | E20: 0.2 | F20: 0.8 | G20: 0.375 | H20: 0.375 | I20: 0.25
B21: Pacific | C21: 0.3 | D21: 0.45 | E21: 0 | F21: 0.75 | G21: 0.4 | H21: 0.6 | I21: 0
B22: Atlantic | C22: 0.3 | D22: 0.4 | E22: 0 | F22: 0.7 | G22: 0.42857143 | H22: 0.57142857 | I22: 0

Sheet LCA Data
B2: Life Cycle Impact Assessment Data
H3: =0.0189*2400*(375/2400) -> 7.0875
B4: 1 Construction and Materials
D6: Embodied | H6: Materials | L6: Transport | P6: Construction | T6: Life Units
B7: Assembly | C7: Material/Type | D7: GWP (kgCO2e) | E7: Energy (MJ) | F7: Water (kg) | G7: ODP (kgCFC11e) | H7: GWP (kgCO2e) | I7: Energy (MJ) | J7: Water (kg) | K7: ODP (kgCFC11e) | L7: GWP (kgCO2e) | M7: Energy (MJ) | N7: Water (kg) | O7: ODP (kgCFC11e) | P7: GWP (kgCO2e) | Q7: Energy (MJ) | R7: Water (kg) | S7: ODP (kgCFC11e) | T7: No. | V7: tanker per tkm
B8: Foundation | C8: Concrete Slab (cy) | D8: =H8+L8+P8 -> 340.28857 | E8: =I8+M8+Q8 -> 2341.1183 | F8: =J8+N8+R8 -> 3971.6893 | G8: =K8+O8+S8 -> 1.3372135e-05 | H8: =0.183+74.2+247 -> 321.383 | I8: =41.868*(0.0446+24.7+24.2) -> 2049.2125 | J8: =1000*(0.000254+0.883+2.95) -> 3833.254 | K8: =2.33*10^-12+3.08*10^-6+8.16*10^-6 -> 1.1240002e-05 | L8: =12.3+0.00557+1.14 -> 13.44557 | M8: =41.868*(4.51+0.00205+0.42) -> 206.49507 | N8: =1000*(0.0438+1.99*10^-5+0.00408) -> 47.8999 | O8: =1.95*10^-6+8.85*10^-10+1.81*10^-7 -> 2.131885e-06 | P8: =5.46 -> 5.46 | Q8: =41.868*(2.04) -> 85.41072 | R8: =1.06*Q8 -> 90.535363 | S8: =2.48*10^-10 -> 2.48e-10 | T8: 1 | V8: gwp | W8: 0.0185
B9: Foundation | C9: Strip Foundation (cy) | D9: =H9+L9+P9 -> 355.4101 | E9: =I9+M9+Q9 -> 2547.5296 | F9: =J9+N9+R9 -> 4149.7762 | G9: =K9+O9+S9 -> 1.4019023e-05 | H9: =0.369+88.9+247 -> 336.269 | I9: =41.868*(0.0896+29.5+24.2) -> 2252.063 | J9: =1000*(0.000511+1.06+2.95) -> 4010.511 | K9: =4.68*10^-12+3.69*10^-6+8.16*10^-6 -> 1.1850005e-05 | L9: =12.3+0.0111+1.37 -> 13.6811 | M9: =41.868*(4.51+0.0041+0.503) -> 210.05594 | N9: =1000*(0.0438+3.98*10^-5+0.00489) -> 48.7298 | O9: =1.95*10^-6+1.77*10^-9+2.17*10^-7 -> 2.16877e-06 | P9: =5.46 -> 5.46 | Q9: =41.868*(2.04) -> 85.41072 | R9: =1.06*Q9 -> 90.535363 | S9: =2.48*10^-10 -> 2.48e-10 | T9: 1 | V9: mj | W9: =0.00567*41.868 -> 0.23739156
B10: Foundation | C10: Mat and Pile (cy) | D10: =H10+L10+P10 -> 356.4021 | E10: =I10+M10+Q10 -> 2564.2149 | F10: =J10+N10+R10 -> 4160.375 | G10: =K10+O10+S10 -> 1.4053237e-05 | H10: =0.737+89.5+247 -> 337.237 | I10: =41.868*(0.179+29.8+24.2) -> 2268.3664 | J10: =1000*(0.00102+1.07+2.95) -> 4021.02 | K10: =9.36*10^-12+3.72*10^-6+8.16*10^-6 -> 1.1880009e-05 | L10: =12.3+0.0251+1.38 -> 13.7051 | M10: =41.868*(4.51+0.00922+0.507) -> 210.43778 | N10: =1000*(0.0438+8.96*10^-5+0.00493) -> 48.8196 | O10: =1.95*10^-6+3.98*10^-9+2.19*10^-7 -> 2.17298e-06 | P10: =5.46 -> 5.46 | Q10: =41.868*(2.04) -> 85.41072 | R10: =1.06*Q10 -> 90.535363 | S10: =2.48*10^-10 -> 2.48e-10 | T10: 1 | V10: water | W10: =0 -> 0
B11: Foundation | C11: Novacem Concrete Slab (cy) | D11: =H11+L11+P11 -> 89.06857 | E11: =I11+M11+Q11 -> 1453.5167 | F11: =J11+N11+R11 -> 3187.2893 | G11: =K11+O11+S11 -> 6.2383353e-06 | H11: =H8+H14 -> 70.163 | I11: =I8+I14 -> 1161.6109 | J11: =J8+J14 -> 3048.854 | K11: =K8+K14 -> 4.1062023e-06 | L11: =12.3+0.00557+1.14 -> 13.44557 | M11: =41.868*(4.51+0.00205+0.42) -> 206.49507 | N11: =1000*(0.0438+1.99*10^-5+0.00408) -> 47.8999 | O11: =1.95*10^-6+8.85*10^-10+1.81*10^-7 -> 2.131885e-06 | P11: =5.46 -> 5.46 | Q11: =41.868*(2.04) -> 85.41072 | R11: =1.06*Q11 -> 90.535363 | S11: =2.48*10^-10 -> 2.48e-10 | T11: 1
B12: Foundation | C12: Novacem Strip Foundation (cy) | D12: =H12+L12+P12 -> 104.1901 | E12: =I12+M12+Q12 -> 1659.928 | F12: =J12+N12+R12 -> 3365.3762 | G12: =K12+O12+S12 -> 6.8852227e-06 | H12: =H9+H14 -> 85.049 | I12: =I9+I14 -> 1364.4614 | J12: =J9+J14 -> 3226.111 | K12: =K9+K14 -> 4.7162047e-06 | L12: =12.3+0.0111+1.37 -> 13.6811 | M12: =41.868*(4.51+0.0041+0.503) -> 210.05594 | N12: =1000*(0.0438+3.98*10^-5+0.00489) -> 48.7298 | O12: =1.95*10^-6+1.77*10^-9+2.17*10^-7 -> 2.16877e-06 | P12: =5.46 -> 5.46 | Q12: =41.868*(2.04) -> 85.41072 | R12: =1.06*Q12 -> 90.535363 | S12: =2.48*10^-10 -> 2.48e-10 | T12: 1
B13: Foundation | C13: Novacem Mat and Pile (cy) | D13: =H13+L13+P13 -> 105.1821 | E13: =I13+M13+Q13 -> 1676.6133 | F13: =J13+N13+R13 -> 3375.975 | G13: =K13+O13+S13 -> 6.9194374e-06 | H13: =H10+H14 -> 86.017 | I13: =I10+I14 -> 1380.7648 | J13: =J10+J14 -> 3236.62 | K13: =K10+K14 -> 4.7462094e-06 | L13: =12.3+0.0251+1.38 -> 13.7051 | M13: =41.868*(4.51+0.00922+0.507) -> 210.43778 | N13: =1000*(0.0438+8.96*10^-5+0.00493) -> 48.8196 | O13: =1.95*10^-6+3.98*10^-9+2.19*10^-7 -> 2.17298e-06 | P13: =5.46 -> 5.46 | Q13: =41.868*(2.04) -> 85.41072 | R13: =1.06*Q13 -> 90.535363 | S13: =2.48*10^-10 -> 2.48e-10 | T13: 1
C14: Novacem Subtraction (per cy concrete) | H14: =-1.06*237 -> -251.22 | I14: =-1.06*20*41.868 -> -887.6016 | J14: =-1.06*0.74*1000 -> -784.4 | K14: =-1.06*6.73*10^-6 -> -7.1338e-06
B15: Interior Wall | C15: Curtain Wall (sf) | D15: =H15+L15+P15 -> 13.85843 | E15: =I15+M15+Q15 -> 189.42431 | F15: =J15+N15+R15 -> 192.01185 | G15: =K15+O15+S15 -> 2.21867e-07 | H15: 2.37 | I15: =41.868*0.667 -> 27.925956 | J15: =1000*0.0215 -> 21.5 | K15: =2.13*10^-7 -> 2.13e-07 | L15: 0.0529 | M15: =41.868*0.0195 -> 0.816426 | N15: =1000*0.000189 -> 0.189 | O15: =8.4*10^-9 -> 8.4e-09 | P15: 11.43553 | Q15: =41.868*3.837822 -> 160.68193 | R15: =1.06*Q15 -> 170.32285 | S15: =4.67*10^-10 -> 4.67e-10 | T15: 1 | V15: odp | W15: =6.9*10^-13 -> 0
B16: Interior Wall | C16: Steel Studs and Painted Gypsum (sf) | D16: =H16+L16+P16 -> 19.783322 | E16: =I16+M16+Q16 -> 284.98961 | F16: =J16+N16+R16 -> 246.80985 | G16: =K16+O16+S16 -> 6.91467e-07 | H16: 7.520218 | I16: =41.868*2.664661 -> 111.56403 | J16: =1000*0.073532 -> 73.532 | K16: =5.6*10^-7 -> 5.6e-07 | L16: =0.827574 -> 0.827574 | M16: =41.868*0.304377 -> 12.743656 | N16: =1000*0.002955 -> 2.955 | O16: =1.31*10^-7 -> 1.31e-07 | P16: 11.43553 | Q16: =41.868*3.837822 -> 160.68193 | R16: =1.06*Q16 -> 170.32285 | S16: =4.67*10^-10 -> 4.67e-10 | T16: 1
B17: Interior Wall | C17: Timber Studs and Painted Gypsum (sf) | D17: =H17+L17+P17 -> 14.716947 | E17: =I17+M17+Q17 -> 213.57993 | F17: =J17+N17+R17 -> 20.553525 | G17: =K17+O17+S17 -> 4.1499906e-07 | H17: 3.0078444 | I17: 48.685306 | J17: 19.576549 | K17: 3.7110689e-07 | L17: 0.27357299 | M17: 4.2127049 | N17: 0.97697622 | O17: 4.3425538e-08 | P17: 11.43553 | Q17: 160.68191 | R17: 0 | S17: 4.6663989e-10 | T17: 1
B18: Interior Wall | C18: Concrete and Painted Gypsum (sf) | D18: =H18+L18+P18 -> 24.518761 | E18: =I18+M18+Q18 -> 307.27882 | F18: =J18+N18+R18 -> 294.5004 | G18: =K18+O18+S18 -> 9.75467e-07 | H18: 11.18845 | I18: 117.4195 | J18: 117.411 | K18: =6.74*10^-7 -> 6.74e-07 | L18: 1.894781 | M18: 29.17742 | N18: 6.76659 | O18: =3.01*10^-7 -> 3.01e-07 | P18: 11.43553 | Q18: 160.6819 | R18: =1.06*Q18 -> 170.32281 | S18: =4.67*10^-10 -> 4.67e-10 | T18: 1
B19: Interior Wall | C19: Painted Concrete (sf) | D19: =H19+L19+P19 -> 22.354943 | E19: =I19+M19+Q19 -> 276.52233 | F19: =J19+N19+R19 -> 281.52428 | G19: =K19+O19+S19 -> 7.15027e-07 | H19: 9.267052 | I19: =90.396 -> 90.396 | J19: =105.3006 -> 105.3006 | K19: =4.52273*10^-7 -> 4.52273e-07 | L19: 1.6523608 | M19: 25.44443 | N19: =5.900865 -> 5.900865 | O19: =2.62287*10^-7 -> 2.62287e-07 | P19: 11.43553 | Q19: 160.6819 | R19: =1.06*Q19 -> 170.32281 | S19: =4.67*10^-10 -> 4.67e-10 | T19: 1
B20: Exterior Wall | C20: Curtain Wall Triple Pane (sf) | D20: =H20+L20+P20 -> 21.782376 | E20: =I20+M20+Q20 -> 284.5765 | F20: =J20+N20+R20 -> 254.1337 | G20: =K20+O20+S20 -> 9.083067e-07 | H20: 10.185233 | I20: 121.40594 | J20: 83.233734 | K20: =8.82186*10^-7 -> 8.82186e-07 | L20: 0.1616137 | M20: 2.4886625 | N20: 0.57715035 | O20: =2.56537*10^-8 -> 2.56537e-08 | P20: 11.43553 | Q20: 160.6819 | R20: =1.06*Q20 -> 170.32281 | S20: =4.67*10^-10 -> 4.67e-10 | T20: 1
B21: Exterior Wall | C21: Curtain Wall Double Pane (sf) | D21: =H21+L21+P21 -> 19.084591 | E21: =I21+M21+Q21 -> 252.3044 | F21: =J21+N21+R21 -> 230.04529 | G21: =K21+O21+S21 -> 6.63752e-07 | H21: 7.54039 | I21: 89.949094 | J21: 59.334392 | K21: =6.46085*10^-7 -> 6.46085e-07 | L21: 0.108671 | M21: 1.673411 | N21: 0.388084 | O21: =1.72*10^-8 -> 1.72e-08 | P21: 11.43553 | Q21: 160.6819 | R21: =1.06*Q21 -> 170.32281 | S21: =4.67*10^-10 -> 4.67e-10 | T21: 1
B22: Exterior Wall | C22: Qbiss Curtain Wall (sf) | D22: =H22+L22+P22 -> 19.990701 | E22: =I22+M22+Q22 -> 262.64616 | F22: =J22+N22+R22 -> 219.53758 | G22: =K22+O22+S22 -> 1.7703051e-06 | H22: 19.784226 | I22: 259.46668 | J22: 218.80022 | K22: 1.7375303e-06 | L22: 0.20647544 | M22: 3.1794809 | N22: 0.73735932 | O22: 3.2774826e-08 | P22: 0 | Q22: 0 | R22: =1.06*Q22 -> 0 | S22: 0 | T22: 1
B23: Exterior Wall | C23: Brick on Concrete (sf) | D23: =H23+L23+P23 -> 26.188723 | E23: =I23+M23+Q23 -> 306.73507 | F23: =J23+N23+R23 -> 118.47896 | G23: =K23+O23+S23 -> 9.750515e-07 | H23: 12.882529 | I23: 117.24712 | J23: 111.7985 | K23: 6.7764551e-07 | L23: 1.8706639 | M23: 28.806041 | N23: 6.6804625 | O23: 2.9693935e-07 | P23: 11.43553 | Q23: 160.68191 | R23: 0 | S23: 4.6663989e-10 | T23: 1
B24: Exterior Wall | C24: Recycled Brick (sf) | D24: =H24+L24+P24 -> 6.0107157 | E24: =I24+M24+Q24 -> 79.64535 | F24: =J24+N24+R24 -> 6.575819 | G24: =K24+O24+S24 -> 6.3326921e-08 | H24: 0.56739704 | I24: 2.8326574 | J24: 5.7066634 | K24: 2.4481704e-08 | L24: 0.24338104 | M24: 3.7477841 | N24: 0.86915558 | O24: 3.8633027e-08 | P24: 5.1999376 | Q24: 73.064908 | R24: 0 | S24: 2.1218941e-10 | T24: 1
B25: Exterior Wall | C25: Concrete Cladding (sf) | D25: =H25+L25+P25 -> 21.28716 | E25: =I25+M25+Q25 -> 255.008 | F25: =J25+N25+R25 -> 274.23756 | G25: =K25+O25+S25 -> 5.61378e-07 | H25: 8.2243467 | I25: 69.267843 | J25: 98.103437 | K25: =3.02605*10^-7 -> 3.02605e-07 | L25: 1.6272828 | M25: 25.058257 | N25: =5.81130697 -> 5.811307 | O25: =2.58306*10^-7 -> 2.58306e-07 | P25: 11.43553 | Q25: 160.6819 | R25: =1.06*Q25 -> 170.32281 | S25: =4.67*10^-10 -> 4.67e-10 | T25: 1
C26: Novacem Subtraction (per sf concrete cladding) | H26: =-1.06*4.37 -> -4.6322 | I26: =-1.06*0.368*41.868 -> -16.331869 | J26: =-1.06*1000*0.0136 -> -14.416 | K26: =-1.06*1.24*10^-7 -> -1.3144e-07
B27: Exterior Wall | C27: Novacem Concrete Cladding (sf) | D27: =H27+L27+P27 -> 16.65496 | E27: =I27+M27+Q27 -> 238.67613 | F27: =J27+N27+R27 -> 259.82156 | G27: =K27+O27+S27 -> 4.29938e-07 | H27: =H25+H26 -> 3.5921467 | I27: =I25+I26 -> 52.935973 | J27: =J25+J26 -> 83.687437 | K27: =K25+K26 -> 1.71165e-07 | L27: 1.6272828 | M27: 25.058257 | N27: =5.81130697 -> 5.811307 | O27: =2.58306*10^-7 -> 2.58306e-07 | P27: 11.43553 | Q27: 160.6819 | R27: =1.06*Q27 -> 170.32281 | S27: =4.67*10^-10 -> 4.67e-10 | T27: 1
B28: Exterior Wall | C28: EIFS on Metal Stud (sf) | D28: =H28+L28+P28 -> 25.053595 | E28: =I28+M28+Q28 -> 364.99427 | F28: =J28+N28+R28 -> 274.25204 | G28: =K28+O28+S28 -> 1.205466e-06 | H28: 12.89359 | I28: 193.1563 | J28: 101.342 | K28: =1.09*10^-6 -> 1.09e-06 | L28: 0.72447523 | M28: 11.156073 | N28: 2.5872226 | O28: =1.14999*10^-7 -> 1.14999e-07 | P28: 11.43553 | Q28: 160.6819 | R28: =1.06*Q28 -> 170.32281 | S28: =4.67*10^-10 -> 4.67e-10 | T28: 1
B29: Exterior Wall | C29: Structurally Insulated Panels (sf) | D29: =H29+L29+P29 -> 8.73 | E29: =I29+M29+Q29 -> 108.5 | F29: =J29+N29+R29 -> 58.0598 | G29: =K29+O29+S29 -> 2.74929e-07 | H29: 4.4 | I29: 46 | J29: 6.86 | K29: 8.78e-08 | L29: 1.18 | M29: 18.17 | N29: 4.21 | O29: 1.87e-07 | P29: 3.15 | Q29: 44.33 | R29: =1.06*Q29 -> 46.9898 | S29: 1.29e-10 | T29: 1
B30: Exterior Wall | C30: Brick on Metal Stud (sf) | D30: =H30+L30+P30 -> 25.199831 | E30: =I30+M30+Q30 -> 335.38775 | F30: =J30+N30+R30 -> 270.41105 | G30: =K30+O30+S30 -> 9.26651e-07 | H30: 12.532693 | I30: 155.74052 | J30: 95.689954 | K30: =7.30685*10^-7 -> 7.30685e-07 | L30: =1.231607891 -> 1.2316079 | M30: =18.96532452 -> 18.965325 | N30: =4.398283696 -> 4.3982837 | O30: =1.95499*10^-7 -> 1.95499e-07 | P30: 11.43553 | Q30: 160.6819 | R30: =1.06*Q30 -> 170.32281 | S30: =4.67*10^-10 -> 4.67e-10 | T30: 1
B31: Floor | C31: Wood System (sf) | D31: =H31+L31+P31 -> 7.937486 | E31: =I31+M31+Q31 -> 109.0056 | F31: =J31+N31+R31 -> 84.468069 | G31: =K31+O31+S31 -> 2.24647e-08 | H31: =3.59 -> 3.59 | I31: =41.868*1.14 -> 47.72952 | J31: =1000*0.0213 -> 21.3 | K31: =9.27*10^-11 -> 0 | L31: =0.14 -> 0.14 | M31: =41.868*0.0515 -> 2.156202 | N31: =1000*0.000501 -> 0.501 | O31: =2.22*10^-8 -> 2.22e-08 | P31: 4.207486 | Q31: =41.868*1.412054 -> 59.119877 | R31: =1.06*Q31 -> 62.667069 | S31: =1.72*10^-10 -> 1.72e-10 | T31: 1
B32: Floor | C32: Concrete (sf) | D32: =H32+L32+P32 -> 11.880086 | E32: =I32+M32+Q32 -> 105.90192 | F32: =J32+N32+R32 -> 150.23457 | G32: =K32+O32+S32 -> 3.0133363e-07 | H32: =1.08+0.128+6.13 -> 7.338 | I32: =41.868*(0.361+0.0311+0.602) -> 41.620979 | J32: =1000*(0.0129+0.000178+0.0733) -> 86.378 | K32: =4.51*10^-8+1.63*10^-12+2.03*10^-7 -> 2.4810163e-07 | L32: =0.304+0.0167+0.0139 -> 0.3346 | M32: =41.868*(0.112+0.00615+0.00512) -> 5.1610684 | N32: =1000*(0.00108+5.97*10^-5+4.98*10^-5) -> 1.1895 | O32: =4.82*10^-8+2.65*10^-9+2.21*10^-9 -> 5.306e-08 | P32: 4.207486 | Q32: =41.868*1.412054 -> 59.119877 | R32: =1.06*Q32 -> 62.667069 | S32: =1.72*10^-10 -> 1.72e-10 | T32: 1
B33: Floor | C33: Concrete and Carpet (sf) | D33: =H33+L33+P33 -> 12.862876 | E33: =I33+M33+Q33 -> 122.33511 | F33: =J33+N33+R33 -> 151.67107 | G33: =K33+O33+S33 -> 3.19777e-07 | H33: 8.31545 | I33: =41.868*1.38484 -> 57.980481 | J33: =1000*0.08779 -> 87.79 | K33: =2.65605*10^-7 -> 2.65605e-07 | L33: 0.33994 | M33: =41.868*0.12503 -> 5.234756 | N33: =1000*0.001214 -> 1.214 | O33: =5.4*10^-8 -> 5.4e-08 | P33: 4.207486 | Q33: =41.868*1.412054 -> 59.119877 | R33: =1.06*Q33 -> 62.667069 | S33: =1.72*10^-10 -> 1.72e-10 | T33: 1
B34: Floor | C34: Concrete and Ceramic (sf) | D34: =H34+L34+P34 -> 16.894459 | E34: =I34+M34+Q34 -> 185.18807 | F34: =J34+N34+R34 -> 194.54207 | G34: =K34+O34+S34 -> 8.99272e-07 | H34: 12.3526 | I34: =41.868*2.888106 -> 120.91922 | J34: =1000*0.130681 -> 130.681 | K34: =8.46*10^-7 -> 8.46e-07 | L34: 0.334373 | M34: =41.868*0.122981 -> 5.1489685 | N34: =1000*0.001194 -> 1.194 | O34: =5.31*10^-8 -> 5.31e-08 | P34: 4.207486 | Q34: =41.868*1.412054 -> 59.119877 | R34: =1.06*Q34 -> 62.667069 | S34: =1.72*10^-10 -> 1.72e-10 | T34: 1
B35: Floor | C35: Bubble Deck (sf) | D35: =H35+L35+P35 -> 9.5098571 | E35: =I35+M35+Q35 -> 72.669925 | F35: =J35+N35+R35 -> 106.85626 | G35: =K35+O35+S35 -> 3.2168865e-07 | H35: 9.0290311 | I35: 65.877819 | J35: 106.76096 | K35: 3.1743417e-07 | L35: 0.026685683 | M35: 0.41092838 | N35: 0.095299165 | O35: 4.235945e-09 | P35: 0.45414038 | Q35: 6.3811775 | R35: 0 | S35: 1.8531718e-11 | T35: 1
B36: Floor | C36: Epicore (sf) | D36: =H36+L36+P36 -> 2.48974 | E36: =I36+M36+Q36 -> 29.623621 | F36: =J36+N36+R36 -> 17.024743 | G36: =K36+O36+S36 -> 1.3298115e-08 | H36: 1.3313426 | I36: 13.286763 | J36: 0.27617941 | K36: 6.1757787e-09 | L36: 0.044583091 | M36: 0.6865276 | N36: 0.15921389 | O36: 7.0768855e-09 | P36: 1.1138143 | Q36: 15.65033 | R36: =1.06*Q36 -> 16.58935 | S36: 4.5450468e-11 | T36: 1
B37: Floor | C37: Novacem Concrete (sf) | D37: =H37+L37+P37 -> 5.710886 | E37: =I37+M37+Q37 -> 84.200065 | F37: =J37+N37+R37 -> 131.04857 | G37: =K37+O37+S37 -> 1.2643363e-07 | H37: =H32+H40 -> 1.1688 | I37: =I32+I40 -> 19.91912 | J37: =J32+J40 -> 67.192 | K37: =K32+K40 -> 7.320163e-08 | L37: =0.304+0.0167+0.0139 -> 0.3346 | M37: =41.868*(0.112+0.00615+0.00512) -> 5.1610684 | N37: =1000*(0.00108+5.97*10^-5+4.98*10^-5) -> 1.1895 | O37: =4.82*10^-8+2.65*10^-9+2.21*10^-9 -> 5.306e-08 | P37: 4.207486 | Q37: =41.868*1.412054 -> 59.119877 | R37: =1.06*Q37 -> 62.667069 | S37: =1.72*10^-10 -> 1.72e-10 | T37: 1
B38: Floor | C38: Novacem Concrete and Carpet (sf) | D38: =H38+L38+P38 -> 6.693676 | E38: =I38+M38+Q38 -> 100.63325 | F38: =J38+N38+R38 -> 132.48507 | G38: =K38+O38+S38 -> 1.44877e-07 | H38: =H33+H40 -> 2.14625 | I38: =I33+I40 -> 36.278622 | J38: =J33+J40 -> 68.604 | K38: =K33+K40 -> 9.0705e-08 | L38: 0.33994 | M38: =41.868*0.12503 -> 5.234756 | N38: =1000*0.001214 -> 1.214 | O38: =5.4*10^-8 -> 5.4e-08 | P38: 4.207486 | Q38: =41.868*1.412054 -> 59.119877 | R38: =1.06*Q38 -> 62.667069 | S38: =1.72*10^-10 -> 1.72e-10 | T38: 1
B39: Floor | C39: Novacem Concrete and Ceramic (sf) | D39: =H39+L39+P39 -> 10.725259 | E39: =I39+M39+Q39 -> 163.48621 | F39: =J39+N39+R39 -> 175.35607 | G39: =K39+O39+S39 -> 7.24372e-07 | H39: =H34+H40 -> 6.1834 | I39: =I34+I40 -> 99.217363 | J39: =J34+J40 -> 111.495 | K39: =K34+K40 -> 6.711e-07 | L39: 0.334373 | M39: =41.868*0.122981 -> 5.1489685 | N39: =1000*0.001194 -> 1.194 | O39: =5.31*10^-8 -> 5.31e-08 | P39: 4.207486 | Q39: =41.868*1.412054 -> 59.119877 | R39: =1.06*Q39 -> 62.667069 | S39: =1.72*10^-10 -> 1.72e-10 | T39: 1
C40: Novacem Subtraction (per sf concrete flooring) | H40: =-1.06*5.82 -> -6.1692 | I40: =-1.06*0.489*41.868 -> -21.701859 | J40: =-1.06*1000*0.0181 -> -19.186 | K40: =-1.06*1.65*10^-7 -> -1.749e-07
B41: Floor | C41: Carpet (sf) | D41: =H41+L41+P41 -> 0.97445716 | E41: =I41+M41+Q41 -> 16.454156 | F41: =J41+N41+R41 -> 1.4284932 | G41: =K41+O41+S41 -> 1.856824e-08 | H41: 0.96888427 | I41: 16.36834 | J41: 1.4085914 | K41: 1.768363e-08 | L41: 0.0055728864 | M41: 0.085815948 | N41: 0.019901736 | O41: 8.8461069e-10 | P41: 0 | Q41: 0 | R41: 0 | S41: 0 | T41: 2
B42: Roof | C42: Steel Structure (sf) | D42: =H42+L42+P42 -> 43.073319 | E42: =I42+M42+Q42 -> 590.53127 | F42: =J42+N42+R42 -> 400.59265 | G42: =K42+O42+S42 -> 1.249933e-06 | H42: 19.69234 | I42: =41.868*6.241408 -> 261.31527 | J42: =1000*0.058126 -> 58.126 | K42: =1.16*10^-6 -> 1.16e-06 | L42: =0.509919 -> 0.509919 | M42: =41.868*0.187546 -> 7.8521759 | N42: =1000*0.001821 -> 1.821 | O42: =8.9*10^-8 -> 8.9e-08 | P42: =22.87106 -> 22.87106 | Q42: =41.868*7.675643 -> 321.36382 | R42: =1.06*Q42 -> 340.64565 | S42: =9.33*10^-10 -> 9.33e-10 | T42: 1
...

Sheet Lists
A1: Pick Assembly | B1: Pick foundation | C1: Pick interior wall | D1: Pick exterior wall | E1: Pick floor | F1: Pick roof | G1: Pick window | H1: Pick columns | I1: Pick beams | J1: Pick MEP | K1: Pick Energy | L1: Pick Misc | M1: Pick Type | N1: Pacific | Q1: Embodied Impacts Breakdown for Each Selected Assembly (from Construction and Materials sheet) | AK1: Carbon Tracker
A2: Foundation | B2: Concrete Slab (cy) | C2: Curtain Wall (sf) | D2: Curtain Wall Triple Pane (sf) | E2: Wood System (sf) | F2: Noxite Membrane (sf) | G2: Single Pane Aluminum Frame (sf) | H2: Reinforced Concrete Column (cy) | I2: Reinforced Concrete Beam (cy) | J2: Stainless Steel Duct (kg) | K2: Photovoltaics (sf) | L2: Nullifire Coating (sf) | N2: Atlantic
A3: Interior Wall | B3: Strip Foundation (cy) | C3: Steel Studs and Painted Gypsum (sf) | D3: Curtain Wall Double Pane (sf) | E3: Concrete (sf) | F3: EPDM Membrane (sf) | G3: Double Pane Aluminum Frame (sf) | H3: Steel Column (kg) | I3: Steel Beam (kg) | J3: Copper Pipe (kg) | K3: Flat Plate Solar Thermal (sf) | L3: C.R. Laurence Shading System (sf) | N3: Ridge | P3: Assembly | Q3: Assembly Type | R3: Amount | S3: Mat. kgCO2 | T3: Trans. kgCO2 | U3: Cons. kgCO2 | V3: Total kgCO2 | W3: Mat. MJ | X3: Trans. MJ | Y3: Cons. MJ | Z3: Total MJ | AA3: Mat. kgH2O | AB3: Trans. kgH2O | AC3: Cons. kgH2O | AD3: Total kgH2O | AE3: Mat. kgCFC11 | AF3: Trans. kgCFC11 | AG3: Cons. kgCFC11 | AH3: Total kgCFC11 | AI3: Plot Name | AK3: Period --> | AL3: 0 | AM3: =AL3+1 -> 1 | AN3: =AM3+1 -> 2 | AO3: =AN3+1 -> 3 | AP3: =AO3+1 -> 4 | AQ3: =AP3+1 -> 5 | AR3: =AQ3+1 -> 6 | AS3: =AR3+1 -> 7 | AT3: =AS3+1 -> 8 | ... CJ3: =CI3+1 -> 50
A4: Exterior Wall | B4: Mat and Pile (cy) | C4: Concrete and Painted Gypsum (sf) | D4: Qbiss Curtain Wall (sf) | E4: Concrete and Carpet (sf) | F4: Polystyrene Insulation (sf) | G4: Triple Pane Aluminum Frame (sf) | H4: Wood Column (kg) | I4: Wood Beam (kg) | J4: Stainless Steel Pipe (kg) | K4: Integrated Solar Water Heating (sf) | L4: Exercise Bike (Bike) | N4: Island | P4: ='Construction and Materials'!B18 -> MEP | Q4: ='Construction and Materials'!C18 -> Stainless Steel Duct (kg) | R4: ='Construction and Materials'!D18 -> 10180.95 | S4: =IF(NOT(Q4="Pick Type"),VLOOKUP(Q4,'LCA Data'!$C$8:$S$107,6,FALSE)*Lists!R4,0) -> 34411.611 | T4: =IF(NOT(Q4="Pick Type"),VLOOKUP(Q4,'LCA Data'!$C$8:$S$107,10,FALSE)*Lists!R4,0) -> 227.03519 | U4: =IF(NOT(Q4="Pick Type"),VLOOKUP(Q4,'LCA Data'!$C$8:$S$107,14,FALSE)*Lists!R4,0) -> 0 | V4: =SUM(S4:U4) -> 34638.646 | W4: =IF(NOT(Q4="Pick Type"),VLOOKUP(Q4,'LCA Data'!$C$8:$S$107,7,FALSE)*Lists!R4,0) -> 273230.11 | X4: =IF(NOT(Q4="Pick Type"),VLOOKUP(Q4,'LCA Data'!$C$8:$S$107,11,FALSE)*Lists!R4,0) -> 3495.2993 | Y4: =IF(NOT(Q4="Pick Type"),VLOOKUP(Q4,'LCA Data'!$C$8:$S$107,15,FALSE)*Lists!R4,0) -> 0 | Z4: =SUM(W4:Y4) -> 276725.4 | AA4: =IF(NOT(Q4="Pick Type"),VLOOKUP(Q4,'LCA Data'!$C$8:$S$107,8,FALSE)*Lists!R4,0) -> 193438.05 | AB4: =IF(NOT(Q4="Pick Type"),VLOOKUP(Q4,'LCA Data'!$C$8:$S$107,12,FALSE)*Lists!R4,0) -> 810.40362 | AC4: =IF(NOT(Q4="Pick Type"),VLOOKUP(Q4,'LCA Data'!$C$8:$S$107,16,FALSE)*Lists!R4,0) -> 0 | AD4: =SUM(AA4:AC4) -> 194248.45 | AE4: =IF(NOT(Q4="Pick Type"),VLOOKUP(Q4,'LCA Data'!$C$8:$S$107,9,FALSE)*Lists!R4,0) -> 0 | AF4: =IF(NOT(Q4="Pick Type"),VLOOKUP(Q4,'LCA Data'!$C$8:$S$107,13,FALSE)*Lists!R4,0) -> 3.6040563e-05 | AG4: =IF(NOT(Q4="Pick Type"),VLOOKUP(Q4,'LCA Data'!$C$8:$S$107,17,FALSE)*Lists!R4,0) -> 0 | AH4: =SUM(AE4:AG4) -> 3.6040563e-05 | AI4: =IF(R4=0,NA(),Q4) -> Stainless Steel Duct (kg) | AK4: Assembly 1 --> | AL4: =V4 -> 34638.646 | AM4: =IF(Q4=$J$14,V4,0) -> 0 | AN4: =IF(Q4=$J$14,V4,0) -> 0 | AO4: =IF(Q4=$J$14,V4,0) -> 0 | AP4: =IF(Q4=$J$14,V4,0) -> 0 | AQ4: =IF(Q4=$J$14,V4,0) -> 0 | AR4: =IF(Q4=$J$14,V4,0) -> 0 | AS4: =IF(Q4=$J$14,V4,0) -> 0 | AT4: =IF(Q4=$J$14,V4,0) -> 0 | AU4: =IF(Q4=$J$14,V4,0) -> 0 | AV4: =IF(Q4=$J$14,V4,0) -> 0 | AW4: =IF(Q4=$J$14,V4,0) -> 0 | AX4: =IF(Q4=$J$14,V4,0) -> 0 | AY4: =IF(Q4=$J$14,V4,0) -> 0 | AZ4: =IF(Q4=$J$14,V4,0) -> 0 | BA4: =IF(Q4=$J$14,V4,0) -> 0 | BB4: =IF(Q4=$J$14,V4,0) -> 0 | BC4: =IF(Q4=$J$14,V4,0) -> 0 | BD4: =IF(Q4=$J$14,V4,0) -> 0 | BE4: =IF(Q4=$J$14,V4,0) -> 0 | BF4: =IF(Q4=$J$14,V4,IF(Q4=$F$2,V4,0)) -> 0 | BG4: =IF(Q4=$J$14,V4,IF(Q4=$J$18,V4,0)) -> 0 | BH4: =IF(Q4=$J$14,V4,0) -> 0 | BI4: =IF(Q4=$J$14,V4,0) -> 0 | BJ4: =IF(Q4=$J$14,V4,IF(Q4=$J$17,V4,IF(Q4=$F$8,V4,0))) -> 0 | BK4: =IF(Q4=$J$7,V4,IF(Q4=$J$8,V4,IF(Q4=$J$9,V4,IF(Q4=$J$14,V4,IF(Q4=$J$10,V4,IF(Q4=$J$11,V4,IF(Q4=$J$12,V4,IF(Q4=$J$13,V4,IF(Q4=$K$5,V4,IF(Q4=$K$7,V4,IF(Q4=$K$3,V4,IF(Q4=$K$9,V4,IF(Q4=$K$10,V4,IF(Q4=$L$6,V4,IF(Q4=$E$10,V4,0))))))))))))))) -> 0 | BL4: =IF(Q4=$J$14,V4,IF(Q4=$L$8,V4,0)) -> 0 | BM4: =IF(Q4=$J$14,V4,0) -> 0 | BN4: =IF(Q4=$J$14,V4,0) -> 0 | BO4: =IF(Q4=$J$14,V4,0) -> 0 | BP4: =IF(Q4=$K$2,V4,IF(Q4=$K$19,V4,IF(Q4=$J$14,V4,IF(Q4=$K$6,V4,0)))) -> 0 | BQ4: =IF(Q4=$J$14,V4,0) -> 0 | BR4: =IF(Q4=$J$14,V4,0) -> 0 | BS4: =IF(Q4=$J$14,V4,0) -> 0 | BT4: =IF(Q4=$J$14,V4,0) -> 0 | BU4: =IF(Q4=$J$14,V4,IF(Q4=$K$4,V4,0)) -> 0 | BV4: =IF(Q4=$J$14,V4,0) -> 0 | BW4: =IF(Q4=$J$14,V4,0) -> 0 | BX4: =IF(Q4=$J$14,V4,0) -> 0 | BY4: =IF(Q4=$J$14,V4,0) -> 0 | BZ4: =IF(P4="Window",V4,IF(Q4=$J$14,V4,IF(Q4=$F$2,V4,0))) -> 0 | CA4: =IF(Q4=$J$14,V4,IF(Q4=$J$18,V4,0)) -> 0 | CB4: =IF(Q4=$J$14,V4,0) -> 0 | CC4: =IF(Q4=$J$14,V4,0) -> 0 | CD4: =IF(Q4=$J$14,V4,0) -> 0 | CE4: =IF(Q4=$J$14,V4,0) -> 0 | CF4: =IF(Q4=$J$14,V4,0) -> 0 | CG4: =IF(Q4=$J$14,V4,0) -> 0 | CH4: =IF(Q4=$J$14,V4,0) -> 0 | CI4: =IF(Q4=$J$14,V4,0) -> 0 | CJ4: =IF(Q4=$J$14,V4,0) -> 0
A5: Floor | B5: Novacem Concrete Slab (cy) | C5: Painted Concrete (sf) | D5: Concrete Cladding (sf) | E5: Concrete and Ceramic (sf) | F5: Fiberglass Insulation (sf) | G5: Single Pane Plastic Frame (sf) | H5: Glulam Column (kg) | I5: Glulam Beam (kg) | J5: HDPE Pipe (kg) | K5: EV Battery (kWh) | L5: Walking Station (Treadmill) | N5: River | P5: ='Construction and Materials'!B19 -> MEP | Q5: ='Construction and Materials'!C19 -> Air Handling Unit (m^3/s) | R5: ='Construction and Materials'!D19 -> 0.78444444 | S5: =IF(NOT(Q5="Pick Type"),VLOOKUP(Q5,'LCA Data'!$C$8:$S$107,6,FALSE)*Lists!R5,0) -> 3153.8499 | T5: =IF(NOT(Q5="Pick Type"),VLOOKUP(Q5,'LCA Data'!$C$8:$S$107,10,FALSE)*Lists!R5,0) -> 12.511889 | U5: =IF(NOT(Q5="Pick Type"),VLOOKUP(Q5,'LCA Data'!$C$8:$S$107,14,FALSE)*Lists!R5,0) -> 0.00061859048 | V5: =SUM(S5:U5) -> 3166.3624 | W5: =IF(NOT(Q5="Pick Type"),VLOOKUP(Q5,'LCA Data'!$C$8:$S$107,7,FALSE)*Lists!R5,0) -> 39435.63 | X5: =IF(NOT(Q5="Pick Type"),VLOOKUP(Q5,'LCA Data'!$C$8:$S$107,11,FALSE)*Lists!R5,0) -> 192.13225 | Y5: =IF(NOT(Q5="Pick Type"),VLOOKUP(Q5,'LCA Data'!$C$8:$S$107,15,FALSE)*Lists!R5,0) -> 0.0086927651 | Z5: =SUM(W5:Y5) -> 39627.771 | AA5: =IF(NOT(Q5="Pick Type"),VLOOKUP(Q5,'LCA Data'!$C$8:$S$107,8,FALSE)*Lists!R5,0) -> 23872.166 | AB5: =IF(NOT(Q5="Pick Type"),VLOOKUP(Q5,'LCA Data'!$C$8:$S$107,12,FALSE)*Lists!R5,0) -> 44.713333 | AC5: =IF(NOT(Q5="Pick Type"),VLOOKUP(Q5,'LCA Data'!$C$8:$S$107,16,FALSE)*Lists!R5,0) -> 0.009214331 | AD5: =SUM(AA5:AC5) -> 23916.889 | AE5: =IF(NOT(Q5="Pick Type"),VLOOKUP(Q5,'LCA Data'!$C$8:$S$107,9,FALSE)*Lists!R5,0) -> 0.00024670778 | AF5: =IF(NOT(Q5="Pick Type"),VLOOKUP(Q5,'LCA Data'!$C$8:$S$107,13,FALSE)*Lists!R5,0) -> 1.9846444e-06 | AG5: =IF(NOT(Q5="Pick Type"),VLOOKUP(Q5,'LCA Data'!$C$8:$S$107,17,FALSE)*Lists!R5,0) -> 0 | AH5: =SUM(AE5:AG5) -> 0.00024869242 | AI5: =IF(R5=0,NA(),Q5) -> Air Handling Unit (m^3/s) | AK5: Assembly 2 --> | AL5: =V5 -> 3166.3624 | AM5: =IF(Q5=$J$14,V5,0) -> 0 | AN5: =IF(Q5=$J$14,V5,0) -> 0 | AO5: =IF(Q5=$J$14,V5,0) -> 0 | AP5: =IF(Q5=$J$14,V5,0) -> 0 | AQ5: =IF(Q5=$J$14,V5,0) -> 0 | AR5: =IF(Q5=$J$14,V5,0) -> 0 | AS5: =IF(Q5=$J$14,V5,0) -> 0 | AT5: =IF(Q5=$J$14,V5,0) -> 0 | AU5: =IF(Q5=$J$14,V5,0) -> 0 | AV5: =IF(Q5=$J$14,V5,0) -> 0 | AW5: =IF(Q5=$J$14,V5,0) -> 0 | AX5: =IF(Q5=$J$14,V5,0) -> 0 | AY5: =IF(Q5=$J$14,V5,0) -> 0 | AZ5: =IF(Q5=$J$14,V5,0) -> 0 | BA5: =IF(Q5=$J$14,V5,0) -> 0 | BB5: =IF(Q5=$J$14,V5,0) -> 0 | BC5: =IF(Q5=$J$14,V5,0) -> 0 | BD5: =IF(Q5=$J$14,V5,0) -> 0 | BE5: =IF(Q5=$J$14,V5,0) -> 0 | BF5: =IF(Q5=$J$14,V5,IF(Q5=$F$2,V5,0)) -> 0 | BG5: =IF(Q5=$J$14,V5,IF(Q5=$J$18,V5,0)) -> 0 | BH5: =IF(Q5=$J$14,V5,0) -> 0 | BI5: =IF(Q5=$J$14,V5,0) -> 0 | BJ5: =IF(Q5=$J$14,V5,IF(Q5=$J$17,V5,IF(Q5=$F$8,V5,0))) -> 0 | BK5: =IF(Q5=$J$7,V5,IF(Q5=$J$8,V5,IF(Q5=$J$9,V5,IF(Q5=$J$14,V5,IF(Q5=$J$10,V5,IF(Q5=$J$11,V5,IF(Q5=$J$12,V5,IF(Q5=$J$13,V5,IF(Q5=$K$5,V5,IF(Q5=$K$7,V5,IF(Q5=$K$3,V5,IF(Q5=$K$9,V5,IF(Q5=$K$10,V5,IF(Q5=$L$6,V5,IF(Q5=$E$10,V5,0))))))))))))))) -> 3166.3624 | BL5: =IF(Q5=$J$14,V5,IF(Q5=$L$8,V5,0)) -> 0 | BM5: =IF(Q5=$J$14,V5,0) -> 0 | BN5: =IF(Q5=$J$14,V5,0) -> 0 | BO5: =IF(Q5=$J$14,V5,0) -> 0 | BP5: =IF(Q5=$K$2,V5,IF(Q5=$K$19,V5,IF(Q5=$J$14,V5,IF(Q5=$K$6,V5,0)))) -> 0 | BQ5: =IF(Q5=$J$14,V5,0) -> 0 | BR5: =IF(Q5=$J$14,V5,0) -> 0 | BS5: =IF(Q5=$J$14,V5,0) -> 0 | BT5: =IF(Q5=$J$14,V5,0) -> 0 | BU5: =IF(Q5=$J$14,V5,IF(Q5=$K$4,V5,0)) -> 0 | BV5: =IF(Q5=$J$14,V5,0) -> 0 | BW5: =IF(Q5=$J$14,V5,0) -> 0 | BX5: =IF(Q5=$J$14,V5,0) -> 0 | BY5: =IF(Q5=$J$14,V5,0) -> 0 | BZ5: =IF(P5="Window",V5,IF(Q5=$J$14,V5,IF(Q5=$F$2,V5,0))) -> 0 | CA5: =IF(Q5=$J$14,V5,IF(Q5=$J$18,V5,0)) -> 0 | CB5: =IF(Q5=$J$14,V5,0) -> 0 | CC5: =IF(Q5=$J$14,V5,0) -> 0 | CD5: =IF(Q5=$J$14,V5,0) -> 0 | CE5: =IF(Q5=$J$14,V5,0) -> 0 | CF5: =IF(Q5=$J$14,V5,0) -> 0 | CG5: =IF(Q5=$J$14,V5,0) -> 0 | CH5: =IF(Q5=$J$14,V5,0) -> 0 | CI5: =IF(Q5=$J$14,V5,0) -> 0 | CJ5: =IF(Q5=$J$14,V5,0) -> 0
